Workbook

Sheet Clientes
A1: Fecha | B1: Negocio | C1: Rubro | D1: Zona | E1: Resenas | F1: Estrellas | G1: Canal | H1: Contacto | I1: Estado | J1: Nota | K1: Dias desde registro | L1: Accion que toca | M1: Fecha del seguimiento
A2: 2026-09-16 | B2: Fonda El Vecino | C2: Fonda | D2: La Chorrera | E2: 7 | F2: 4.9 | G2: WhatsApp | H2: 6490-2318 | I2: pendiente | J2: top2 fondas 13/51 | K2: =IFERROR(DATEDIF(DATEVALUE(A2),TODAY(),"d"),"") -> 20 | L2: =IF(OR(E2="",H2="",H2="anotado sin numero"),"Sin info, no aplica",IF(I2="no","Cerrado, no volver a tocar",IF(I2="vendido","Cliente, no prospectar",IF(I2="respondio","Atender la conversacion hoy",IF(I2="enviado",IF(K2>=1,"Mandar seguimiento (24-48h)","Esperar respuesta"),"Enviar primer mensaje"))))) -> Enviar primer mensaje | M2: =IF(OR(L2="Sin info, no aplica",L2="Cerrado, no volver a tocar",L2="Cliente, no prospectar"),"",IF(I2="enviado",DATEVALUE(A2)+2,IF(I2="respondio",TODAY(),"")))
A3: 2026-09-16 | B3: Los Olivos Fonda | C3: Fonda | D3: La Chorrera | E3: 1 | F3: 5 | G3: WhatsApp | H3: 6632-4207 | I3: pendiente | J3: top2 fondas 13/51 | K3: =IFERROR(DATEDIF(DATEVALUE(A3),TODAY(),"d"),"") -> 20 | L3: =IF(OR(E3="",H3="",H3="anotado sin numero"),"Sin info, no aplica",IF(I3="no","Cerrado, no volver a tocar",IF(I3="vendido","Cliente, no prospectar",IF(I3="respondio","Atender la conversacion hoy",IF(I3="enviado",IF(K3>=1,"Mandar seguimiento (24-48h)","Esperar respuesta"),"Enviar primer mensaje"))))) -> Enviar primer mensaje | M3: =IF(OR(L3="Sin info, no aplica",L3="Cerrado, no volver a tocar",L3="Cliente, no prospectar"),"",IF(I3="enviado",DATEVALUE(A3)+2,IF(I3="respondio",TODAY(),"")))
A4: 2026-09-16 | B4: Fonda Mis Ángeles | C4: Fonda | D4: La Chorrera | E4: 3 | F4: 5 | G4: WhatsApp | H4: 6819-9842 | I4: pendiente | J4: top2 fondas 13/51 | K4: =IFERROR(DATEDIF(DATEVALUE(A4),TODAY(),"d"),"") -> 20 | L4: =IF(OR(E4="",H4="",H4="anotado sin numero"),"Sin info, no aplica",IF(I4="no","Cerrado, no volver a tocar",IF(I4="vendido","Cliente, no prospectar",IF(I4="respondio","Atender la conversacion hoy",IF(I4="enviado",IF(K4>=1,"Mandar seguimiento (24-48h)","Esperar respuesta"),"Enviar primer mensaje"))))) -> Enviar primer mensaje | M4: =IF(OR(L4="Sin info, no aplica",L4="Cerrado, no volver a tocar",L4="Cliente, no prospectar"),"",IF(I4="enviado",DATEVALUE(A4)+2,IF(I4="respondio",TODAY(),"")))
A5: 2026-09-16 | B5: Fonda donde Luis y Matias | C5: Fonda | D5: La Chorrera | E5: 6 | F5: 4.7 | G5: WhatsApp | H5: 6388-6700 | I5: pendiente | J5: contesta reseñas; top2 13/51 | K5: =IFERROR(DATEDIF(DATEVALUE(A5),TODAY(),"d"),"") -> 20 | L5: =IF(OR(E5="",H5="",H5="anotado sin numero"),"Sin info, no aplica",IF(I5="no","Cerrado, no volver a tocar",IF(I5="vendido","Cliente, no prospectar",IF(I5="respondio","Atender la conversacion hoy",IF(I5="enviado",IF(K5>=1,"Mandar seguimiento (24-48h)","Esperar respuesta"),"Enviar primer mensaje"))))) -> Enviar primer mensaje | M5: =IF(OR(L5="Sin info, no aplica",L5="Cerrado, no volver a tocar",L5="Cliente, no prospectar"),"",IF(I5="enviado",DATEVALUE(A5)+2,IF(I5="respondio",TODAY(),"")))
A6: 2026-09-16 | B6: Fonda Damiana | C6: Fonda | D6: La Chorrera | E6: 2 | F6: 5 | G6: WhatsApp | H6: 6856-5394 | I6: pendiente | J6: ficha sin reclamar | K6: =IFERROR(DATEDIF(DATEVALUE(A6),TODAY(),"d"),"") -> 20 | L6: =IF(OR(E6="",H6="",H6="anotado sin numero"),"Sin info, no aplica",IF(I6="no","Cerrado, no volver a tocar",IF(I6="vendido","Cliente, no prospectar",IF(I6="respondio","Atender la conversacion hoy",IF(I6="enviado",IF(K6>=1,"Mandar seguimiento (24-48h)","Esperar respuesta"),"Enviar primer mensaje"))))) -> Enviar primer mensaje | M6: =IF(OR(L6="Sin info, no aplica",L6="Cerrado, no volver a tocar",L6="Cliente, no prospectar"),"",IF(I6="enviado",DATEVALUE(A6)+2,IF(I6="respondio",TODAY(),"")))
A7: 2026-09-16 | B7: Fonda Genin | C7: Fonda | D7: La Chorrera | E7: 4 | F7: 5 | G7: WhatsApp | H7: 6742-6019 | I7: pendiente | J7: ficha sin reclamar | K7: =IFERROR(DATEDIF(DATEVALUE(A7),TODAY(),"d"),"") -> 20 | L7: =IF(OR(E7="",H7="",H7="anotado sin numero"),"Sin info, no aplica",IF(I7="no","Cerrado, no volver a tocar",IF(I7="vendido","Cliente, no prospectar",IF(I7="respondio","Atender la conversacion hoy",IF(I7="enviado",IF(K7>=1,"Mandar seguimiento (24-48h)","Esperar respuesta"),"Enviar primer mensaje"))))) -> Enviar primer mensaje | M7: =IF(OR(L7="Sin info, no aplica",L7="Cerrado, no volver a tocar",L7="Cliente, no prospectar"),"",IF(I7="enviado",DATEVALUE(A7)+2,IF(I7="respondio",TODAY(),"")))
A8: 2026-09-16 | B8: Diabliko's restaurante | C8: Restaurante | D8: La Chorrera | E8: 14 | F8: 4.9 | G8: WhatsApp | H8: 6075-0745 | I8: pendiente | J8: top2 restaurantes 114/273 | K8: =IFERROR(DATEDIF(DATEVALUE(A8),TODAY(),"d"),"") -> 20 | L8: =IF(OR(E8="",H8="",H8="anotado sin numero"),"Sin info, no aplica",IF(I8="no","Cerrado, no volver a tocar",IF(I8="vendido","Cliente, no prospectar",IF(I8="respondio","Atender la conversacion hoy",IF(I8="enviado",IF(K8>=1,"Mandar seguimiento (24-48h)","Esperar respuesta"),"Enviar primer mensaje"))))) -> Enviar primer mensaje | M8: =IF(OR(L8="Sin info, no aplica",L8="Cerrado, no volver a tocar",L8="Cliente, no prospectar"),"",IF(I8="enviado",DATEVALUE(A8)+2,IF(I8="respondio",TODAY(),"")))
A9: 2026-09-16 | B9: DelyChoza | C9: Restaurante | D9: La Chorrera | E9: 1 | F9: 5 | G9: WhatsApp | H9: 6974-3347 | I9: pendiente | J9: top2 restaurantes 114/273 | K9: =IFERROR(DATEDIF(DATEVALUE(A9),TODAY(),"d"),"") -> 20 | L9: =IF(OR(E9="",H9="",H9="anotado sin numero"),"Sin info, no aplica",IF(I9="no","Cerrado, no volver a tocar",IF(I9="vendido","Cliente, no prospectar",IF(I9="respondio","Atender la conversacion hoy",IF(I9="enviado",IF(K9>=1,"Mandar seguimiento (24-48h)","Esperar respuesta"),"Enviar primer mensaje"))))) -> Enviar primer mensaje | M9: =IF(OR(L9="Sin info, no aplica",L9="Cerrado, no volver a tocar",L9="Cliente, no prospectar"),"",IF(I9="enviado",DATEVALUE(A9)+2,IF(I9="respondio",TODAY(),"")))
A10: 2026-09-16 | B10: XILOKA | C10: Comida rápida | D10: La Chorrera | E10: 13 | F10: 4.7 | G10: WhatsApp | H10: 6545-1152 | I10: pendiente | J10: ficha marcada posible cierre | K10: =IFERROR(DATEDIF(DATEVALUE(A10),TODAY(),"d"),"") -> 20 | L10: =IF(OR(E10="",H10="",H10="anotado sin numero"),"Sin info, no aplica",IF(I10="no","Cerrado, no volver a tocar",IF(I10="vendido","Cliente, no prospectar",IF(I10="respondio","Atender la conversacion hoy",IF(I10="enviado",IF(K10>=1,"Mandar seguimiento (24-48h)","Esperar respuesta"),"Enviar primer mensaje"))))) -> Enviar primer mensaje | M10: =IF(OR(L10="Sin info, no aplica",L10="Cerrado, no volver a tocar",L10="Cliente, no prospectar"),"",IF(I10="enviado",DATEVALUE(A10)+2,IF(I10="respondio",TODAY(),"")))
A11: 2026-09-16 | B11: RiQras Hechas con Amor | C11: Comida rápida | D11: La Chorrera | E11: 8 | F11: 4.4 | G11: WhatsApp | H11: 6922-8108 | I11: pendiente | J11: top2 comida rápida 207/397 | K11: =IFERROR(DATEDIF(DATEVALUE(A11),TODAY(),"d"),"") -> 20 | L11: =IF(OR(E11="",H11="",H11="anotado sin numero"),"Sin info, no aplica",IF(I11="no","Cerrado, no volver a tocar",IF(I11="vendido","Cliente, no prospectar",IF(I11="respondio","Atender la conversacion hoy",IF(I11="enviado",IF(K11>=1,"Mandar seguimiento (24-48h)","Esperar respuesta"),"Enviar primer mensaje"))))) -> Enviar primer mensaje | M11: =IF(OR(L11="Sin info, no aplica",L11="Cerrado, no volver a tocar",L11="Cliente, no prospectar"),"",IF(I11="enviado",DATEVALUE(A11)+2,IF(I11="respondio",TODAY(),"")))
A12: 2026-09-16 | B12: Delirios Zulianos | C12: Restaurante | D12: La Chorrera | E12: 1 | F12: 5 | G12: WhatsApp | H12: 6010-0077 | I12: pendiente | J12: top2 restaurantes 114/273 | K12: =IFERROR(DATEDIF(DATEVALUE(A12),TODAY(),"d"),"") -> 20 | L12: =IF(OR(E12="",H12="",H12="anotado sin numero"),"Sin info, no aplica",IF(I12="no","Cerrado, no volver a tocar",IF(I12="vendido","Cliente, no prospectar",IF(I12="respondio","Atender la conversacion hoy",IF(I12="enviado",IF(K12>=1,"Mandar seguimiento (24-48h)","Esperar respuesta"),"Enviar primer mensaje"))))) -> Enviar primer mensaje | M12: =IF(OR(L12="Sin info, no aplica",L12="Cerrado, no volver a tocar",L12="Cliente, no prospectar"),"",IF(I12="enviado",DATEVALUE(A12)+2,IF(I12="respondio",TODAY(),"")))
A13: 2026-09-16 | B13: Fonda Anyie | C13: Fonda | D13: La Chorrera | E13: 6 | F13: 4.8 | G13: llamada | H13: 254-4159 | I13: pendiente | J13: llamar; ficha sin reclamar | K13: =IFERROR(DATEDIF(DATEVALUE(A13),TODAY(),"d"),"") -> 20 | L13: =IF(OR(E13="",H13="",H13="anotado sin numero"),"Sin info, no aplica",IF(I13="no","Cerrado, no volver a tocar",IF(I13="vendido","Cliente, no prospectar",IF(I13="respondio","Atender la conversacion hoy",IF(I13="enviado",IF(K13>=1,"Mandar seguimiento (24-48h)","Esperar respuesta"),"Enviar primer mensaje"))))) -> Enviar primer mensaje | M13: =IF(OR(L13="Sin info, no aplica",L13="Cerrado, no volver a tocar",L13="Cliente, no prospectar"),"",IF(I13="enviado",DATEVALUE(A13)+2,IF(I13="respondio",TODAY(),"")))
... A100: 2026-09-25 | B100: Clinica Dental La Vision | C100: Clinica dental | D100: La Chorrera | E100: 11 | F100: 5 | G100: llamada | H100: 258-8068 | I100: pendiente | J100: llamar | K100: =IFERROR(DATEDIF(DATEVALUE(A100),TODAY(),"d"),"") -> 11 | L100: =IF(OR(E100="",H100="",H100="anotado sin numero"),"Sin info, no aplica",IF(I100="no","Cerrado, no volver a tocar",IF(I100="vendido","Cliente, no prospectar",IF(I100="respondio","Atender la conversacion hoy",IF(I100="enviado",IF(K100>=1,"Mandar seguimiento (24-48h)","Esperar respuesta"),"Enviar primer mensaje"))))) -> Enviar primer mensaje | M100: =IF(OR(L100="Sin info, no aplica",L100="Cerrado, no volver a tocar",L100="Cliente, no prospectar"),"",IF(I100="enviado",DATEVALUE(A100)+2,IF(I100="respondio",TODAY(),"")))
A101: 2026-09-26 | B101: Mary (negocio por confirmar) | C101: Por confirmar | D101: Visita sabado | G101: visita | H101: 6916-8931 | I101: pendiente | J101: el empleado paso el contacto del encargado 26-09; no hubo conversacion previa; falta saber el rubro | K101: =IFERROR(DATEDIF(DATEVALUE(A101),TODAY(),"d"),"") -> 10 | L101: =IF(OR(E101="",H101="",H101="anotado sin numero"),"Sin info, no aplica",IF(I101="no","Cerrado, no volver a tocar",IF(I101="vendido","Cliente, no prospectar",IF(I101="respondio","Atender la conversacion hoy",IF(I101="enviado",IF(K101>=1,"Mandar seguimiento (24-48h)","Esperar respuesta"),"Enviar primer mensaje"))))) -> Sin info, no aplica | M101: =IF(OR(L101="Sin info, no aplica",L101="Cerrado, no volver a tocar",L101="Cliente, no prospectar"),"",IF(I101="enviado",DATEVALUE(A101)+2,IF(I101="respondio",TODAY(),"")))
A102: 2026-09-26 | B102: Sin nombre | C102: Por confirmar | D102: Visita sabado | G102: visita | H102: 6302-5460 | I102: pendiente | J102: el empleado paso el contacto del encargado 26-09; no hubo conversacion previa; sin nombre ni rubro | K102: =IFERROR(DATEDIF(DATEVALUE(A102),TODAY(),"d"),"") -> 10 | L102: =IF(OR(E102="",H102="",H102="anotado sin numero"),"Sin info, no aplica",IF(I102="no","Cerrado, no volver a tocar",IF(I102="vendido","Cliente, no prospectar",IF(I102="respondio","Atender la conversacion hoy",IF(I102="enviado",IF(K102>=1,"Mandar seguimiento (24-48h)","Esperar respuesta"),"Enviar primer mensaje"))))) -> Sin info, no aplica | M102: =IF(OR(L102="Sin info, no aplica",L102="Cerrado, no volver a tocar",L102="Cliente, no prospectar"),"",IF(I102="enviado",DATEVALUE(A102)+2,IF(I102="respondio",TODAY(),"")))
A103: 2026-09-26 | B103: Jonas la Islas | C103: Por confirmar | D103: Visita sabado | G103: visita | H103: 6347-6877 | I103: pendiente | J103: el empleado paso el contacto del encargado 26-09; no hubo conversacion previa | K103: =IFERROR(DATEDIF(DATEVALUE(A103),TODAY(),"d"),"") -> 10 | L103: =IF(OR(E103="",H103="",H103="anotado sin numero"),"Sin info, no aplica",IF(I103="no","Cerrado, no volver a tocar",IF(I103="vendido","Cliente, no prospectar",IF(I103="respondio","Atender la conversacion hoy",IF(I103="enviado",IF(K103>=1,"Mandar seguimiento (24-48h)","Esperar respuesta"),"Enviar primer mensaje"))))) -> Sin info, no aplica | M103: =IF(OR(L103="Sin info, no aplica",L103="Cerrado, no volver a tocar",L103="Cliente, no prospectar"),"",IF(I103="enviado",DATEVALUE(A103)+2,IF(I103="respondio",TODAY(),"")))
A104: 2026-09-26 | B104: Suchi Expres (Fatima Guevara) | C104: Comida | D104: Visita sabado | G104: visita | H104: 6579-5750 | I104: no | J104: franquicia, la decision no esta en el local; retomar solo si el encargado resulta dueno de ese local | K104: =IFERROR(DATEDIF(DATEVALUE(A104),TODAY(),"d"),"") -> 10 | L104: =IF(OR(E104="",H104="",H104="anotado sin numero"),"Sin info, no aplica",IF(I104="no","Cerrado, no volver a tocar",IF(I104="vendido","Cliente, no prospectar",IF(I104="respondio","Atender la conversacion hoy",IF(I104="enviado",IF(K104>=1,"Mandar seguimiento (24-48h)","Esperar respuesta"),"Enviar primer mensaje"))))) -> Sin info, no aplica | M104: =IF(OR(L104="Sin info, no aplica",L104="Cerrado, no volver a tocar",L104="Cliente, no prospectar"),"",IF(I104="enviado",DATEVALUE(A104)+2,IF(I104="respondio",TODAY(),"")))
A105: 2026-09-26 | B105: Privana | C105: Por confirmar | D105: Visita sabado | G105: visita | H105: 6406-9577 | I105: pendiente | J105: el empleado paso el contacto del encargado 26-09; no hubo conversacion previa | K105: =IFERROR(DATEDIF(DATEVALUE(A105),TODAY(),"d"),"") -> 10 | L105: =IF(OR(E105="",H105="",H105="anotado sin numero"),"Sin info, no aplica",IF(I105="no","Cerrado, no volver a tocar",IF(I105="vendido","Cliente, no prospectar",IF(I105="respondio","Atender la conversacion hoy",IF(I105="enviado",IF(K105>=1,"Mandar seguimiento (24-48h)","Esperar respuesta"),"Enviar primer mensaje"))))) -> Sin info, no aplica | M105: =IF(OR(L105="Sin info, no aplica",L105="Cerrado, no volver a tocar",L105="Cliente, no prospectar"),"",IF(I105="enviado",DATEVALUE(A105)+2,IF(I105="respondio",TODAY(),"")))
A106: 2026-09-26 | B106: Quiro JYS | C106: Por confirmar | D106: Visita sabado | G106: visita | H106: anotado sin numero | I106: pendiente | J106: falta contacto; buscar en Maps | K106: =IFERROR(DATEDIF(DATEVALUE(A106),TODAY(),"d"),"") -> 10 | L106: =IF(OR(E106="",H106="",H106="anotado sin numero"),"Sin info, no aplica",IF(I106="no","Cerrado, no volver a tocar",IF(I106="vendido","Cliente, no prospectar",IF(I106="respondio","Atender la conversacion hoy",IF(I106="enviado",IF(K106>=1,"Mandar seguimiento (24-48h)","Esperar respuesta"),"Enviar primer mensaje"))))) -> Sin info, no aplica | M106: =IF(OR(L106="Sin info, no aplica",L106="Cerrado, no volver a tocar",L106="Cliente, no prospectar"),"",IF(I106="enviado",DATEVALUE(A106)+2,IF(I106="respondio",TODAY(),"")))
A107: 2026-09-26 | B107: Animal Clinic | C107: Veterinaria | D107: Visita sabado | G107: visita | H107: anotado sin numero | I107: pendiente | J107: falta contacto; buscar en Maps | K107: =IFERROR(DATEDIF(DATEVALUE(A107),TODAY(),"d"),"") -> 10 | L107: =IF(OR(E107="",H107="",H107="anotado sin numero"),"Sin info, no aplica",IF(I107="no","Cerrado, no volver a tocar",IF(I107="vendido","Cliente, no prospectar",IF(I107="respondio","Atender la conversacion hoy",IF(I107="enviado",IF(K107>=1,"Mandar seguimiento (24-48h)","Esperar respuesta"),"Enviar primer mensaje"))))) -> Sin info, no aplica | M107: =IF(OR(L107="Sin info, no aplica",L107="Cerrado, no volver a tocar",L107="Cliente, no prospectar"),"",IF(I107="enviado",DATEVALUE(A107)+2,IF(I107="respondio",TODAY(),"")))
A108: 2026-09-26 | B108: Laboratorio Ventus (Dainelis Rivera) | C108: Laboratorio | D108: Visita sabado | G108: correo | H108: dainelis-rivera@lavoratorioventus.com | I108: pendiente | J108: verificar dominio antes de escribir | K108: =IFERROR(DATEDIF(DATEVALUE(A108),TODAY(),"d"),"") -> 10 | L108: =IF(OR(E108="",H108="",H108="anotado sin numero"),"Sin info, no aplica",IF(I108="no","Cerrado, no volver a tocar",IF(I108="vendido","Cliente, no prospectar",IF(I108="respondio","Atender la conversacion hoy",IF(I108="enviado",IF(K108>=1,"Mandar seguimiento (24-48h)","Esperar respuesta"),"Enviar primer mensaje"))))) -> Sin info, no aplica | M108: =IF(OR(L108="Sin info, no aplica",L108="Cerrado, no volver a tocar",L108="Cliente, no prospectar"),"",IF(I108="enviado",DATEVALUE(A108)+2,IF(I108="respondio",TODAY(),"")))
A109: 2026-09-26 | B109: Unbox | C109: Por confirmar | D109: Visita sabado | G109: correo | H109: unboxadmn@gmail.com | I109: pendiente | J109: el empleado paso el contacto del encargado 26-09; no hubo conversacion previa | K109: =IFERROR(DATEDIF(DATEVALUE(A109),TODAY(),"d"),"") -> 10 | L109: =IF(OR(E109="",H109="",H109="anotado sin numero"),"Sin info, no aplica",IF(I109="no","Cerrado, no volver a tocar",IF(I109="vendido","Cliente, no prospectar",IF(I109="respondio","Atender la conversacion hoy",IF(I109="enviado",IF(K109>=1,"Mandar seguimiento (24-48h)","Esperar respuesta"),"Enviar primer mensaje"))))) -> Sin info, no aplica | M109: =IF(OR(L109="Sin info, no aplica",L109="Cerrado, no volver a tocar",L109="Cliente, no prospectar"),"",IF(I109="enviado",DATEVALUE(A109)+2,IF(I109="respondio",TODAY(),"")))
A110: 2026-09-26 | B110: Jimmy Deporte | C110: Deportes | D110: Visita sabado | G110: correo | H110: retail@ y mercadeo@ (dominio ilegible en la foto) | I110: pendiente | J110: confirmar dominio con Jimmy antes de escribir | K110: =IFERROR(DATEDIF(DATEVALUE(A110),TODAY(),"d"),"") -> 10 | L110: =IF(OR(E110="",H110="",H110="anotado sin numero"),"Sin info, no aplica",IF(I110="no","Cerrado, no volver a tocar",IF(I110="vendido","Cliente, no prospectar",IF(I110="respondio","Atender la conversacion hoy",IF(I110="enviado",IF(K110>=1,"Mandar seguimiento (24-48h)","Esperar respuesta"),"Enviar primer mensaje"))))) -> Sin info, no aplica | M110: =IF(OR(L110="Sin info, no aplica",L110="Cerrado, no volver a tocar",L110="Cliente, no prospectar"),"",IF(I110="enviado",DATEVALUE(A110)+2,IF(I110="respondio",TODAY(),"")))
A111: 2026-09-26 | B111: Hombre de la Macha | C111: Por confirmar | D111: Visita sabado | G111: correo | H111: mercadeo@hombredelamacha.com | I111: pendiente | J111: el empleado paso el contacto del encargado 26-09; no hubo conversacion previa | K111: =IFERROR(DATEDIF(DATEVALUE(A111),TODAY(),"d"),"") -> 10 | L111: =IF(OR(E111="",H111="",H111="anotado sin numero"),"Sin info, no aplica",IF(I111="no","Cerrado, no volver a tocar",IF(I111="vendido","Cliente, no prospectar",IF(I111="respondio","Atender la conversacion hoy",IF(I111="enviado",IF(K111>=1,"Mandar seguimiento (24-48h)","Esperar respuesta"),"Enviar primer mensaje"))))) -> Sin info, no aplica | M111: =IF(OR(L111="Sin info, no aplica",L111="Cerrado, no volver a tocar",L111="Cliente, no prospectar"),"",IF(I111="enviado",DATEVALUE(A111)+2,IF(I111="respondio",TODAY(),"")))
A112: 2026-09-26 | B112: Liszeth | C112: Por confirmar | D112: Visita sabado | G112: correo | H112: liszeths787@gmail.com | I112: pendiente | J112: el empleado paso el contacto del encargado 26-09; no hubo conversacion previa | K112: =IFERROR(DATEDIF(DATEVALUE(A112),TODAY(),"d"),"") -> 10 | L112: =IF(OR(E112="",H112="",H112="anotado sin numero"),"Sin info, no aplica",IF(I112="no","Cerrado, no volver a tocar",IF(I112="vendido","Cliente, no prospectar",IF(I112="respondio","Atender la conversacion hoy",IF(I112="enviado",IF(K112>=1,"Mandar seguimiento (24-48h)","Esperar respuesta"),"Enviar primer mensaje"))))) -> Sin info, no aplica | M112: =IF(OR(L112="Sin info, no aplica",L112="Cerrado, no volver a tocar",L112="Cliente, no prospectar"),"",IF(I112="enviado",DATEVALUE(A112)+2,IF(I112="respondio",TODAY(),"")))
A113: 2026-09-28 | B113: Clinica Dr Candanedo | C113: Clinica dental | D113: Arraijan | E113: 17 | F113: 5 | G113: WhatsApp | H113: 6786-0431 | I113: pendiente | J113: top2 dentales Arraijan 84/43 | K113: =IFERROR(DATEDIF(DATEVALUE(A113),TODAY(),"d"),"") -> 8 | L113: =IF(OR(E113="",H113="",H113="anotado sin numero"),"Sin info, no aplica",IF(I113="no","Cerrado, no volver a tocar",IF(I113="vendido","Cliente, no prospectar",IF(I113="respondio","Atender la conversacion hoy",IF(I113="enviado",IF(K113>=1,"Mandar seguimiento (24-48h)","Esperar respuesta"),"Enviar primer mensaje"))))) -> Enviar primer mensaje | M113: =IF(OR(L113="Sin info, no aplica",L113="Cerrado, no volver a tocar",L113="Cliente, no prospectar"),"",IF(I113="enviado",DATEVALUE(A113)+2,IF(I113="respondio",TODAY(),"")))
A114: 2026-09-28 | B114: Clinica Dental Arraijan Cabecera | C114: Clinica dental | D114: Arraijan Cabecera | E114: 8 | F114: 5 | G114: WhatsApp | H114: 6594-1827 | I114: pendiente | J114: equipo periapical; top2 84/43 | K114: =IFERROR(DATEDIF(DATEVALUE(A114),TODAY(),"d"),"") -> 8 | L114: =IF(OR(E114="",H114="",H114="anotado sin numero"),"Sin info, no aplica",IF(I114="no","Cerrado, no volver a tocar",IF(I114="vendido","Cliente, no prospectar",IF(I114="respondio","Atender la conversacion hoy",IF(I114="enviado",IF(K114>=1,"Mandar seguimiento (24-48h)","Esperar respuesta"),"Enviar primer mensaje"))))) -> Enviar primer mensaje | M114: =IF(OR(L114="Sin info, no aplica",L114="Cerrado, no volver a tocar",L114="Cliente, no prospectar"),"",IF(I114="enviado",DATEVALUE(A114)+2,IF(I114="respondio",TODAY(),"")))
A115: 2026-09-28 | B115: Clinica Dental Spa | C115: Clinica dental | D115: Vista Alegre (Arraijan) | E115: 11 | F115: 4.6 | G115: WhatsApp | H115: 6444-4552 | I115: pendiente | J115: correo dentalspavistalegre@gmail.com; top2 84/43 | K115: =IFERROR(DATEDIF(DATEVALUE(A115),TODAY(),"d"),"") -> 8 | L115: =IF(OR(E115="",H115="",H115="anotado sin numero"),"Sin info, no aplica",IF(I115="no","Cerrado, no volver a tocar",IF(I115="vendido","Cliente, no prospectar",IF(I115="respondio","Atender la conversacion hoy",IF(I115="enviado",IF(K115>=1,"Mandar seguimiento (24-48h)","Esperar respuesta"),"Enviar primer mensaje"))))) -> Enviar primer mensaje | M115: =IF(OR(L115="Sin info, no aplica",L115="Cerrado, no volver a tocar",L115="Cliente, no prospectar"),"",IF(I115="enviado",DATEVALUE(A115)+2,IF(I115="respondio",TODAY(),"")))
A116: 2026-09-28 | B116: Clinica Carvajal | C116: Clinica especializada | D116: Arraijan (Tatcher) | E116: 7 | F116: 4.4 | G116: WhatsApp | H116: 6321-9041 | I116: pendiente | J116: diagonal a la policlinica; top2 84/43 | K116: =IFERROR(DATEDIF(DATEVALUE(A116),TODAY(),"d"),"") -> 8 | L116: =IF(OR(E116="",H116="",H116="anotado sin numero"),"Sin info, no aplica",IF(I116="no","Cerrado, no volver a tocar",IF(I116="vendido","Cliente, no prospectar",IF(I116="respondio","Atender la conversacion hoy",IF(I116="enviado",IF(K116>=1,"Mandar seguimiento (24-48h)","Esperar respuesta"),"Enviar primer mensaje"))))) -> Enviar primer mensaje | M116: =IF(OR(L116="Sin info, no aplica",L116="Cerrado, no volver a tocar",L116="Cliente, no prospectar"),"",IF(I116="enviado",DATEVALUE(A116)+2,IF(I116="respondio",TODAY(),"")))
A117: 2026-09-28 | B117: OESTE VETS ARRAIJAN | C117: Veterinaria | D117: Arraijan | E117: 6 | F117: 4.3 | G117: WhatsApp | H117: 6920-1993 | I117: pendiente | J117: top2 veterinarias 78/64 | K117: =IFERROR(DATEDIF(DATEVALUE(A117),TODAY(),"d"),"") -> 8 | L117: =IF(OR(E117="",H117="",H117="anotado sin numero"),"Sin info, no aplica",IF(I117="no","Cerrado, no volver a tocar",IF(I117="vendido","Cliente, no prospectar",IF(I117="respondio","Atender la conversacion hoy",IF(I117="enviado",IF(K117>=1,"Mandar seguimiento (24-48h)","Esperar respuesta"),"Enviar primer mensaje"))))) -> Enviar primer mensaje | M117: =IF(OR(L117="Sin info, no aplica",L117="Cerrado, no volver a tocar",L117="Cliente, no prospectar"),"",IF(I117="enviado",DATEVALUE(A117)+2,IF(I117="respondio",TODAY(),"")))
A118: 2026-09-28 | B118: Copytekpty | C118: Imprenta | D118: Arraijan (Loma Coba) | E118: 17 | F118: 4.9 | G118: WhatsApp | H118: 6778-0621 | I118: pendiente | J118: tiene web; imprentas Oeste 26/94 | K118: =IFERROR(DATEDIF(DATEVALUE(A118),TODAY(),"d"),"") -> 8 | L118: =IF(OR(E118="",H118="",H118="anotado sin numero"),"Sin info, no aplica",IF(I118="no","Cerrado, no volver a tocar",IF(I118="vendido","Cliente, no prospectar",IF(I118="respondio","Atender la conversacion hoy",IF(I118="enviado",IF(K118>=1,"Mandar seguimiento (24-48h)","Esperar respuesta"),"Enviar primer mensaje"))))) -> Enviar primer mensaje | M118: =IF(OR(L118="Sin info, no aplica",L118="Cerrado, no volver a tocar",L118="Cliente, no prospectar"),"",IF(I118="enviado",DATEVALUE(A118)+2,IF(I118="respondio",TODAY(),"")))
A119: 2026-09-28 | B119: Strong Body Gym | C119: Gimnasio | D119: Arraijan | E119: 14 | F119: 4.6 | G119: WhatsApp | H119: 6936-9139 | I119: pendiente | J119: cierra 10pm; top2 gimnasios 60/449 | K119: =IFERROR(DATEDIF(DATEVALUE(A119),TODAY(),"d"),"") -> 8 | L119: =IF(OR(E119="",H119="",H119="anotado sin numero"),"Sin info, no aplica",IF(I119="no","Cerrado, no volver a tocar",IF(I119="vendido","Cliente, no prospectar",IF(I119="respondio","Atender la conversacion hoy",IF(I119="enviado",IF(K119>=1,"Mandar seguimiento (24-48h)","Esperar respuesta"),"Enviar primer mensaje"))))) -> Enviar primer mensaje | M119: =IF(OR(L119="Sin info, no aplica",L119="Cerrado, no volver a tocar",L119="Cliente, no prospectar"),"",IF(I119="enviado",DATEVALUE(A119)+2,IF(I119="respondio",TODAY(),"")))
A120: 2026-09-28 | B120: Burunga Fitness Club | C120: Gimnasio | D120: Burunga (Arraijan) | E120: 2 | F120: 5 | G120: WhatsApp | H120: 6018-0588 | I120: pendiente | J120: top2 gimnasios 60/449 | K120: =IFERROR(DATEDIF(DATEVALUE(A120),TODAY(),"d"),"") -> 8 | L120: =IF(OR(E120="",H120="",H120="anotado sin numero"),"Sin info, no aplica",IF(I120="no","Cerrado, no volver a tocar",IF(I120="vendido","Cliente, no prospectar",IF(I120="respondio","Atender la conversacion hoy",IF(I120="enviado",IF(K120>=1,"Mandar seguimiento (24-48h)","Esperar respuesta"),"Enviar primer mensaje"))))) -> Enviar primer mensaje | M120: =IF(OR(L120="Sin info, no aplica",L120="Cerrado, no volver a tocar",L120="Cliente, no prospectar"),"",IF(I120="enviado",DATEVALUE(A120)+2,IF(I120="respondio",TODAY(),"")))
A121: 2026-09-28 | B121: Silueta y Forma Gym | C121: Gimnasio | D121: Arraijan | E121: 4 | F121: 5 | G121: WhatsApp | H121: 6283-1440 | I121: pendiente | J121: tiene web; top2 gimnasios 60/449 | K121: =IFERROR(DATEDIF(DATEVALUE(A121),TODAY(),"d"),"") -> 8 | L121: =IF(OR(E121="",H121="",H121="anotado sin numero"),"Sin info, no aplica",IF(I121="no","Cerrado, no volver a tocar",IF(I121="vendido","Cliente, no prospectar",IF(I121="respondio","Atender la conversacion hoy",IF(I121="enviado",IF(K121>=1,"Mandar seguimiento (24-48h)","Esperar respuesta"),"Enviar primer mensaje"))))) -> Enviar primer mensaje | M121: =IF(OR(L121="Sin info, no aplica",L121="Cerrado, no volver a tocar",L121="Cliente, no prospectar"),"",IF(I121="enviado",DATEVALUE(A121)+2,IF(I121="respondio",TODAY(),"")))
A122: 2026-09-28 | B122: Distribuidora Ahorro Arraijan | C122: Mayorista | D122: Arraijan | E122: 7 | F122: 4.7 | G122: WhatsApp | H122: 6780-0888 | I122: pendiente | J122: top2 de su busqueda 567/253 | K122: =IFERROR(DATEDIF(DATEVALUE(A122),TODAY(),"d"),"") -> 8 | L122: =IF(OR(E122="",H122="",H122="anotado sin numero"),"Sin info, no aplica",IF(I122="no","Cerrado, no volver a tocar",IF(I122="vendido","Cliente, no prospectar",IF(I122="respondio","Atender la conversacion hoy",IF(I122="enviado",IF(K122>=1,"Mandar seguimiento (24-48h)","Esperar respuesta"),"Enviar primer mensaje"))))) -> Enviar primer mensaje | M122: =IF(OR(L122="Sin info, no aplica",L122="Cerrado, no volver a tocar",L122="Cliente, no prospectar"),"",IF(I122="enviado",DATEVALUE(A122)+2,IF(I122="respondio",TODAY(),"")))
A123: 2026-09-28 | B123: Consultorio Medico Panama | C123: Consultorio | D123: Arraijan | E123: 12 | F123: 4.7 | G123: llamada | H123: 344-9264 | I123: pendiente | J123: llamar | K123: =IFERROR(DATEDIF(DATEVALUE(A123),TODAY(),"d"),"") -> 8 | L123: =IF(OR(E123="",H123="",H123="anotado sin numero"),"Sin info, no aplica",IF(I123="no","Cerrado, no volver a tocar",IF(I123="vendido","Cliente, no prospectar",IF(I123="respondio","Atender la conversacion hoy",IF(I123="enviado",IF(K123>=1,"Mandar seguimiento (24-48h)","Esperar respuesta"),"Enviar primer mensaje"))))) -> Enviar primer mensaje | M123: =IF(OR(L123="Sin info, no aplica",L123="Cerrado, no volver a tocar",L123="Cliente, no prospectar"),"",IF(I123="enviado",DATEVALUE(A123)+2,IF(I123="respondio",TODAY(),"")))
A124: 2026-09-28 | B124: Medic & Dental Center | C124: Clinica dental | D124: Nuevo Arraijan | E124: 25 | F124: 4.5 | G124: llamada | H124: 251-0650 | I124: pendiente | J124: llamar | K124: =IFERROR(DATEDIF(DATEVALUE(A124),TODAY(),"d"),"") -> 8 | L124: =IF(OR(E124="",H124="",H124="anotado sin numero"),"Sin info, no aplica",IF(I124="no","Cerrado, no volver a tocar",IF(I124="vendido","Cliente, no prospectar",IF(I124="respondio","Atender la conversacion hoy",IF(I124="enviado",IF(K124>=1,"Mandar seguimiento (24-48h)","Esperar respuesta"),"Enviar primer mensaje"))))) -> Enviar primer mensaje | M124: =IF(OR(L124="Sin info, no aplica",L124="Cerrado, no volver a tocar",L124="Cliente, no prospectar"),"",IF(I124="enviado",DATEVALUE(A124)+2,IF(I124="respondio",TODAY(),"")))
... A151: 2026-09-28 | B151: Materiales de Construccion Super Precio | C151: Materiales construccion | D151: Arraijan | E151: 36 | F151: 4.6 | G151: llamada | H151: 344-0988 | I151: pendiente | J151: vendedora; llamar | K151: =IFERROR(DATEDIF(DATEVALUE(A151),TODAY(),"d"),"") -> 8 | L151: =IF(OR(E151="",H151="",H151="anotado sin numero"),"Sin info, no aplica",IF(I151="no","Cerrado, no volver a tocar",IF(I151="vendido","Cliente, no prospectar",IF(I151="respondio","Atender la conversacion hoy",IF(I151="enviado",IF(K151>=1,"Mandar seguimiento (24-48h)","Esperar respuesta"),"Enviar primer mensaje"))))) -> Enviar primer mensaje | M151: =IF(OR(L151="Sin info, no aplica",L151="Cerrado, no volver a tocar",L151="Cliente, no prospectar"),"",IF(I151="enviado",DATEVALUE(A151)+2,IF(I151="respondio",TODAY(),"")))
A152: 2026-09-28 | B152: BAC Credomatic Panama | C152: Banco | D152: Nacional | G152: correo | H152: mercadeodigital@pa.bac.net | I152: respondio | J152: escribi a afiliados@pa.bac.net; Servicio al Cliente (Laysa Espinosa) refirio a Mercadeo Digital el 28-09; reenviada propuesta con PDF | K152: =IFERROR(DATEDIF(DATEVALUE(A152),TODAY(),"d"),"") -> 8 | L152: =IF(OR(E152="",H152="",H152="anotado sin numero"),"Sin info, no aplica",IF(I152="no","Cerrado, no volver a tocar",IF(I152="vendido","Cliente, no prospectar",IF(I152="respondio","Atender la conversacion hoy",IF(I152="enviado",IF(K152>=1,"Mandar seguimiento (24-48h)","Esperar respuesta"),"Enviar primer mensaje"))))) -> Sin info, no aplica | M152: =IF(OR(L152="Sin info, no aplica",L152="Cerrado, no volver a tocar",L152="Cliente, no prospectar"),"",IF(I152="enviado",DATEVALUE(A152)+2,IF(I152="respondio",TODAY(),"")))
...

Sheet Como usarlo
A1: Como usarlo
A3: Columna que editas | B3: Estado (columna I). Todo lo demas se calcula solo.
A4: Valores de Estado | B4: pendiente / enviado / respondio / vendido / no
A6: Que hace cada valor
A7: pendiente | B7: Todavia no le has escrito. Accion: enviar el primer mensaje.
A8: enviado | B8: Ya mandaste el primero. A las 24 o 48 horas toca el seguimiento, uno solo.
A9: respondio | B9: Te contesto. Accion: atenderlo hoy mismo, responder en menos de 90 segundos sostiene la conversacion en 50 a 60% de los casos.
A10: vendido | B10: Ya compro. Sale de prospeccion.
A11: no | B11: No contesto el seguimiento o cerro. No se vuelve a tocar.
A13: Regla de los que no tienen info | B13: Si la fila no tiene numero de resenas o no tiene contacto, la columna Accion dice "Sin info, no aplica" y no se le arma seguimiento. Primero hay que completar el dato en Maps.
A15: Limite diario | B15: 10 a 15 mensajes enviados a mano. Mas que eso, o automatizado, y WhatsApp bloquea el numero.
A16: Fuente | B16: PROSPECCION.md, seccion 5 del proyecto NFC. Exportado el 2026-10-06.

Sheet Resumen
A1: Estado | B1: Negocios
A2: pendiente | B2: =COUNTIF(Clientes!$I$2:$I$280,A2) -> 266
A3: enviado | B3: =COUNTIF(Clientes!$I$2:$I$280,A3) -> 0
A4: respondio | B4: =COUNTIF(Clientes!$I$2:$I$280,A4) -> 10
A5: vendido | B5: =COUNTIF(Clientes!$I$2:$I$280,A5) -> 1
A6: no | B6: =COUNTIF(Clientes!$I$2:$I$280,A6) -> 2
A7: Sin info (no aplica) | B7: =COUNTIF(Clientes!$L$2:$L$280,"Sin info, no aplica") -> 13
A8: Total | B8: =COUNTA(Clientes!$B$2:$B$280) -> 279
